[2025-05-27 15:24:45 +0000] [371] [ERROR] Exception in worker process
Traceback (most recent call last):
  File "/home/runner/workspace/notifier.py", line 36, in _load_config
    with open('whatsapp_config.json', 'r') as f:
         ^^^^^^^^^^^^^^^^^^^^^^^^^^^^^^^^^
FileNotFoundError: [Errno 2] No such file or directory: 'whatsapp_config.json'

During handling of the above exception, another exception occurred:

Traceback (most recent call last):
  File "/home/runner/workspace/.pythonlibs/lib/python3.11/site-packages/gunicorn/arbiter.py", line 608, in spawn_worker
    worker.init_process()
  File "/home/runner/workspace/.pythonlibs/lib/python3.11/site-packages/gunicorn/workers/base.py", line 135, in init_process
    self.load_wsgi()
  File "/home/runner/workspace/.pythonlibs/lib/python3.11/site-packages/gunicorn/workers/base.py", line 147, in load_wsgi
    self.wsgi = self.app.wsgi()
                ^^^^^^^^^^^^^^^
  File "/home/runner/workspace/.pythonlibs/lib/python3.11/site-packages/gunicorn/app/base.py", line 66, in wsgi
    self.callable = self.load()
                    ^^^^^^^^^^^
  File "/home/runner/workspace/.pythonlibs/lib/python3.11/site-packages/gunicorn/app/wsgiapp.py", line 57, in load
    return self.load_wsgiapp()
           ^^^^^^^^^^^^^^^^^^^
  File "/home/runner/workspace/.pythonlibs/lib/python3.11/site-packages/gunicorn/app/wsgiapp.py", line 47, in load_wsgiapp
    return util.import_app(self.app_uri)
           ^^^^^^^^^^^^^^^^^^^^^^^^^^^^^
  File "/home/runner/workspace/.pythonlibs/lib/python3.11/site-packages/gunicorn/util.py", line 370, in import_app
    mod = importlib.import_module(module)
          ^^^^^^^^^^^^^^^^^^^^^^^^^^^^^^^
  File "/nix/store/clx0mcir7qw8zk36zbr4jra789g3knf6-python3-3.11.10/lib/python3.11/importlib/__init__.py", line 126, in import_module
    return _bootstrap._gcd_import(name[level:], package, level)
           ^^^^^^^^^^^^^^^^^^^^^^^^^^^^^^^^^^^^^^^^^^^^^^^^^^^^
  File "<frozen importlib._bootstrap>", line 1204, in _gcd_import
  File "<frozen importlib._bootstrap>", line 1176, in _find_and_load
  File "<frozen importlib._bootstrap>", line 1147, in _find_and_load_unlocked
  File "<frozen importlib._bootstrap>", line 690, in _load_unlocked
  File "<frozen importlib._bootstrap_external>", line 940, in exec_module
  File "<frozen importlib._bootstrap>", line 241, in _call_with_frames_removed
  File "/home/runner/workspace/main.py", line 2, in <module>
    from app import app
  File "/home/runner/workspace/app.py", line 42, in <module>
    from routes import *
  File "/home/runner/workspace/routes.py", line 9, in <module>
    from scheduler import run_manual_task
  File "/home/runner/workspace/scheduler.py", line 520, in <module>
    daily_scheduler = DailyTaskScheduler()
                      ^^^^^^^^^^^^^^^^^^^^
  File "/home/runner/workspace/scheduler.py", line 28, in __init__
    self.notification_manager = NotificationManager()
                                ^^^^^^^^^^^^^^^^^^^^^
  File "/home/runner/workspace/notifier.py", line 225, in __init__
    self.whatsapp_notifier = WhatsAppNotifier()
                             ^^^^^^^^^^^^^^^^^^
  File "/home/runner/workspace/notifier.py", line 14, in __init__
    self.config = self._load_config()
                  ^^^^^^^^^^^^^^^^^^^
  File "/home/runner/workspace/notifier.py", line 41, in _load_config
    'enabled': bool(Config.TWILIO_ACCOUNT_SID),
                    ^^^^^^^^^^^^^^^^^^^^^^^^^
AttributeError: type object 'Config' has no attribute 'TWILIO_ACCOUNT_SID'
[2025-05-27 15:24:45 +0000] [371] [INFO] Worker exiting (pid: 371)
[2025-05-27 15:24:46 +0000] [156] [ERROR] Worker (pid:371) exited with code 3
[2025-05-27 15:24:46 +0000] [156] [ERROR] Shutting down: Master
[2025-05-27 15:24:46 +0000] [156] [ERROR] Reason: Worker failed to boot.